run_effect_size_simulations_beta_epsilon_greedy.py:116: RuntimeWarning: divide by zero encountered in double_scalars
  wald_type_stat = (mean_1 - mean_2)/SE #(P^hat_A - P^hat_b)/SE
run_effect_size_simulations_beta_epsilon_greedy.py:127: RuntimeWarning: divide by zero encountered in long_scalars
  cur_row['ratio'] = sample_sizes[0] / sample_sizes[1]
run_effect_size_simulations_beta_epsilon_greedy.py:182: RuntimeWarning: invalid value encountered in true_divide
  w = math.sqrt(sum(sum((prob_table_h1-prob_table_h0)**2/prob_table_h0)))
run_effect_size_simulations_beta_epsilon_greedy.py:116: RuntimeWarning: invalid value encountered in double_scalars
  wald_type_stat = (mean_1 - mean_2)/SE #(P^hat_A - P^hat_b)/SE
Traceback (most recent call last):
  File "/usr/local/lib64/python3.6/site-packages/pandas/core/indexes/base.py", line 2897, in get_loc
    return self._engine.get_loc(key)
  File "pandas/_libs/index.pyx", line 107, in pandas._libs.index.IndexEngine.get_loc
  File "pandas/_libs/index.pyx", line 131, in pandas._libs.index.IndexEngine.get_loc
  File "pandas/_libs/hashtable_class_helper.pxi", line 1607, in pandas._libs.hashtable.PyObjectHashTable.get_item
  File "pandas/_libs/hashtable_class_helper.pxi", line 1614, in pandas._libs.hashtable.PyObjectHashTable.get_item
KeyError: 'Action1SuccessCount'

During handling of the above exception, another exception occurred:

Traceback (most recent call last):
  File "run_effect_size_simulations_beta_epsilon_greedy.py", line 577, in <module>
    main()
  File "run_effect_size_simulations_beta_epsilon_greedy.py", line 490, in main
    arm_df_by_trial = create_arm_stats_by_step(outfile_directory, num_sims, step_sizes[-1], num_arms)
  File "run_effect_size_simulations_beta_epsilon_greedy.py", line 78, in create_arm_stats_by_step
    mean_dfs = [output_file[successHeader] / (output_file[successHeader] + output_file[failureHeader]) for successHeader, failureHeader in zip(successes, failures)]
  File "run_effect_size_simulations_beta_epsilon_greedy.py", line 78, in <listcomp>
    mean_dfs = [output_file[successHeader] / (output_file[successHeader] + output_file[failureHeader]) for successHeader, failureHeader in zip(successes, failures)]
  File "/usr/local/lib64/python3.6/site-packages/pandas/core/frame.py", line 2995, in __getitem__
    indexer = self.columns.get_loc(key)
  File "/usr/local/lib64/python3.6/site-packages/pandas/core/indexes/base.py", line 2899, in get_loc
    return self._engine.get_loc(self._maybe_cast_indexer(key))
  File "pandas/_libs/index.pyx", line 107, in pandas._libs.index.IndexEngine.get_loc
  File "pandas/_libs/index.pyx", line 131, in pandas._libs.index.IndexEngine.get_loc
  File "pandas/_libs/hashtable_class_helper.pxi", line 1607, in pandas._libs.hashtable.PyObjectHashTable.get_item
  File "pandas/_libs/hashtable_class_helper.pxi", line 1614, in pandas._libs.hashtable.PyObjectHashTable.get_item
KeyError: 'Action1SuccessCount'
